<?xml version="1.0"?>
<!--
Software License Agreement (BSD)
\file      jaco.urdf.xacro
\authors   Patrick Hussey
\copyright Copyright (c) 2015, Stanley Innovation, Inc., All rights reserved.
Redistribution and use in source and binary forms, with or without modification, are permitted provided that
the following conditions are met:
 * Redistributions of source code must retain the above copyright notice, this list of conditions and the
   following disclaimer.
 * Redistributions in binary form must reproduce the above copyright notice, this list of conditions and the
   following disclaimer in the documentation and/or other materials provided with the distribution.
 * Neither the name of Stanley Innovation nor the names of its contributors may be used to endorse or promote
   products derived from this software without specific prior written permission.
THIS SOFTWARE IS PROVIDED BY THE COPYRIGHT HOLDERS AND CONTRIBUTORS "AS IS" AND ANY EXPRESS OR IMPLIED WAR-
RANTIES, INCLUDING, BUT NOT LIMITED TO, THE IMPLIED WARRANTIES OF MERCHANTABILITY AND FITNESS FOR A PARTICULAR
PURPOSE ARE DISCLAIMED. IN NO EVENT SHALL THE COPYRIGHT HOLDER OR CONTRIBUTORS BE LIABLE FOR ANY DIRECT, IN-
DIRECT, INCIDENTAL, SPECIAL, EXEMPLARY, OR CONSEQUENTIAL DAMAGES (INCLUDING, BUT NOT LIMITED TO, PROCUREMENT
OF SUBSTITUTE GOODS OR SERVICES; LOSS OF USE, DATA, OR PROFITS; OR BUSINESS INTERRUPTION) HOWEVER CAUSED AND
ON ANY THEORY OF LIABILITY, WHETHER IN CONTRACT, STRICT LIABILITY, OR TORT (INCLUDING NEGLIGENCE OR OTHERWISE)
ARISING IN ANY WAY OUT OF THE USE OF THIS SOFTWARE, EVEN IF ADVISED OF THE POSSIBILITY OF SUCH DAMAGE.
-->
<robot name="jaco_robot" xmlns:xacro="http://www.ros.org/wiki/xacro">
    <xacro:include filename="$(find vector_description)/urdf/manipulation/jaco/jaco.transmission.xacro" />

    <property name="M_PI" value="3.14159265"/>

    <!-- Inertia parameters -->
    <property name="base_mass" value="0.752103" />
    <property name="shoulder_mass" value="0.839784" />
    <property name="upper_arm_mass" value="0.968862" />
    <property name="forearm_mass" value="0.709960" />
    <property name="wrist_1_mass" value="0.441232" />
    <property name="wrist_2_mass" value="0.441232" />
    <property name="wrist_3_mass" value="0.363290" />

    <xacro:macro name="jaco_robot" params="prefix parent *origin">
        
        <joint name="${prefix}kinova_joint" type="fixed">
            <parent link="${parent}" />
            <child link = "${prefix}base_link" />
            <xacro:insert_block name="origin"/>
        </joint>
        
        <link name="${prefix}base_link" >
            <visual>
                <geometry>
                <mesh filename="package://vector_description/meshes/manipulation/jaco/visual/base.dae"/>
                </geometry>
            </visual>
            <collision>
                <geometry>
                <mesh filename="package://vector_description/meshes/manipulation/jaco/collision/base.stl"/>
                </geometry>
            </collision>
            <inertial>
                <mass value="${base_mass}" />
                <origin xyz="0 0 0" />
                <inertia  ixx="0.009025"  ixy="-0.000002"  ixz="-0.000005" 
                          iyx="-0.000002"  iyy="0.009007"  iyz="0.000000" 
                          izx="-0.000005"  izy="0.000000"  izz="0.000704" />
            </inertial>
        </link>

        <joint name="${prefix}shoulder_pan_joint" type="continuous">
            <parent link="${prefix}base_link" />
            <child link = "${prefix}shoulder_link" />
            <origin xyz="0 0 0.15675" rpy="${M_PI} 0 ${M_PI}" />
            <axis xyz="0 0 1" />
            <limit effort="1800.0" velocity="0.314"/>
            <dynamics damping="0.0" friction="0.0"/>
        </joint>

        <link name="${prefix}shoulder_link">
            <visual>
                <geometry>
                    <mesh filename="package://vector_description/meshes/manipulation/jaco/visual/shoulder.dae"/>
                </geometry>
            </visual>
            <collision>
                <geometry>
                    <mesh filename="package://vector_description/meshes/manipulation/jaco/collision/shoulder.stl"/>
                </geometry>
            </collision>
            <inertial>
                <mass value="${shoulder_mass}" />
                <origin xyz="0 0 0" />
                <inertia  ixx="0.005735"  ixy="0.000000"  ixz="0.000000" 
                          iyx="0.000000"  iyy="0.005801"  iyz="0.000496" 
                          izx="0.000000"  izy="0.000496"  izz="0.000570" />
            </inertial>
        </link>

        <joint name="${prefix}shoulder_lift_joint" type="revolute">
            <parent link="${prefix}shoulder_link" />
            <child link = "${prefix}upper_arm_link" />
            <!--ZERO CONFIG:<origin xyz="0 0 -0.11875" rpy="${M_PI/2} ${M_PI/2} 0" />-->
            <origin xyz="0 0 -0.11875" rpy="${M_PI/2} ${-M_PI/2} 0" />
            <axis xyz="0 0 1" />
            <!--ZERO CONFIG:<limit lower="-2.238" upper="2.238" effort="3000.5" velocity="0.314"/>-->
            <limit lower="${M_PI-2.238}" upper="${M_PI+2.238}" effort="3000.5" velocity="0.314"/>
            <dynamics damping="0.0" friction="0.0"/>
        </joint>

        <link name="${prefix}upper_arm_link">
            <visual>
                <geometry>
                    <mesh filename="package://vector_description/meshes/manipulation/jaco/visual/upper_arm.dae"/>
                </geometry>
            </visual>
            <collision>
                <geometry>
                    <mesh filename="package://vector_description/meshes/manipulation/jaco/collision/upper_arm.stl"/>
                </geometry>
            </collision>
            <inertial>
                <mass value="${upper_arm_mass}" />
                <origin xyz="0 0 0" />
                <inertia  ixx="0.000789"  ixy="0.000008"  ixz="-0.002914" 
                          iyx="0.000008"  iyy="0.069034"  iyz="-0.000001" 
                          izx="-0.002914"  izy="-0.000001"  izz="0.069005" />
            </inertial>
        </link>

        <joint name="${prefix}elbow_joint" type="revolute">
            <parent link="${prefix}upper_arm_link" />
            <child link = "${prefix}forearm_link" />
            <!--ZERO CONFIG:<origin xyz="0.41 0 0.00975" rpy=" 0 ${M_PI} ${M_PI}" />-->
            <origin xyz="0.41 0 0.00975" rpy="0 ${M_PI} 0" />
            <axis xyz="0 0 1" />
            <!--ZERO CONFIG:<limit lower="-2.809" upper="2.809" effort="1800.0" velocity="0.314"/>-->
            <limit lower="${M_PI-2.809}" upper="${M_PI+2.809}" effort="1800.0" velocity="0.314"/>
            <dynamics damping="0.0" friction="0.0"/>
        </joint>

        <link name="${prefix}forearm_link">
            <visual>
                <geometry>
                    <mesh filename="package://vector_description/meshes/manipulation/jaco/visual/forearm.dae"/>
                </geometry>
            </visual>
            <collision>
                <geometry>
                    <mesh filename="package://vector_description/meshes/manipulation/jaco/collision/forearm.stl"/>
                </geometry>
            </collision>
            <inertial>
                <mass value="${forearm_mass}" />
                <origin xyz="0 0 0" />
                <inertia  ixx="0.000341"  ixy="0.000003"  ixz="-0.000034" 
                          iyx="0.000003"  iyy="0.008491"  iyz="-0.000000" 
                          izx="-0.000034"  izy="0.000000"  izz="0.008612" />
            </inertial>
        </link>

        <joint name="${prefix}wrist_1_joint" type="continuous">
            <parent link="${prefix}forearm_link" />
            <child link = "${prefix}wrist_1_link" />
            <origin xyz="0.20725 0 0 " rpy="0 -${M_PI/2} 0" />
            <axis xyz="0 0 1" />
            <limit effort="600.8" velocity="0.785"/>
            <dynamics damping="0.0" friction="0.0"/>
        </joint>

        <link name="${prefix}wrist_1_link">
            <visual>
                <geometry>
                    <mesh filename="package://vector_description/meshes/manipulation/jaco/visual/wrist_1.dae"/>
                </geometry>
            </visual>
            <collision>
                <geometry>
                    <mesh filename="package://vector_description/meshes/manipulation/jaco/collision/wrist_1.stl"/>
                </geometry>
            </collision>
            <inertial>
                <mass value="${wrist_1_mass}" />
                <origin xyz="0 0 0" />
                <inertia  ixx="0.000924"  ixy="0.000000"  ixz="-0.000294" 
                          iyx="0.000000"  iyy="0.001034"  iyz="0.000000" 
                          izx="-0.000294"  izy="0.000000"  izz="0.000312" />
            </inertial>
        </link>

        <joint name="${prefix}wrist_2_joint" type="continuous">
            <parent link="${prefix}wrist_1_link" />
            <child link = "${prefix}wrist_2_link" />
            <origin xyz="0 0 -0.04275704" rpy="0 ${M_PI/3} ${M_PI}" />
            <axis xyz="0 0 1" />
            <limit effort="600.8" velocity="0.785"/>
            <dynamics damping="0.0" friction="0.0"/>
        </joint>

        <link name="${prefix}wrist_2_link">
            <visual>
                <geometry>
                    <mesh filename="package://vector_description/meshes/manipulation/jaco/visual/wrist_2.dae"/>
                </geometry>
            </visual>
            <collision>
                <geometry>
                    <mesh filename="package://vector_description/meshes/manipulation/jaco/collision/wrist_2.stl"/>
                </geometry>
            </collision>
            <inertial>
                <mass value="${wrist_2_mass}" />
                <origin xyz="0 0 0" />
                <inertia  ixx="0.003063"  ixy="0.000000"  ixz="-0.000522" 
                          iyx="0.000000"  iyy="0.003174"  iyz="-0.000001" 
                          izx="-0.000522"  izy="-0.000001"  izz="0.000312" />
            </inertial>
        </link>

        <joint name="${prefix}wrist_3_joint" type="continuous">
            <parent link="${prefix}wrist_2_link" />
            <child link = "${prefix}wrist_3_link" />
            <origin xyz="0 0 -0.08551408" rpy="0 -${M_PI/3} 0" />
            <axis xyz="0 0 1" />
            <limit effort="600.8" velocity="0.785"/>
            <dynamics damping="0.0" friction="0.0"/>
        </joint>
        

        <link name="${prefix}wrist_3_link">
            <visual>
                <geometry>
                    <mesh filename="package://vector_description/meshes/manipulation/jaco/visual/wrist_3.dae"/>
                </geometry>
            </visual>
            <collision>
                <geometry>
                    <mesh filename="package://vector_description/meshes/manipulation/jaco/collision/wrist_3.stl"/>
                </geometry>
            </collision>
            <inertial>
                <mass value="${wrist_3_mass}" />
                <origin xyz="0 0 0" />
                <inertia  ixx="0.001908"  ixy="0.000000"  ixz="0.000000" 
                          iyx="0.000000"  iyy="0.001907"  iyz="0.000000" 
                          izx="0.000000"  izy="0.000001"  izz="0.000209" />
            </inertial>
        </link>

        <joint name="${prefix}ee_fixed_joint" type="fixed">
            <parent link="${prefix}wrist_3_link" />
            <child link = "${prefix}ee_base" />
            <origin xyz="0 0 -0.09380704" rpy="${M_PI} ${M_PI/2} 0" /> <!--0.09380704156-->
        </joint>

        <link name="${prefix}ee_base"/>
 
        <!-- Add in an EEF link for the center of the gripper -->
        <joint name="${prefix}ee_gripper" type="fixed">
            <parent link="${prefix}ee_base" />
            <child link ="${prefix}ee_link" />
            <origin xyz="0.13 0 0" />
        </joint>

        <link name="${prefix}ee_link"/>
        
        <xacro:jaco_arm_transmission prefix="${prefix}" />

  </xacro:macro>
</robot>
