<?xml version="1.0"?>
<!--
Software License Agreement (BSD)
\file      pan_tilt_kinect_one.urdf.xacro
\authors   Patrick Hussey
\copyright Copyright (c) 2015, Stanley Innovation, Inc., All rights reserved.
Redistribution and use in source and binary forms, with or without modification, are permitted provided that
the following conditions are met:
 * Redistributions of source code must retain the above copyright notice, this list of conditions and the
   following disclaimer.
 * Redistributions in binary form must reproduce the above copyright notice, this list of conditions and the
   following disclaimer in the documentation and/or other materials provided with the distribution.
 * Neither the name of Stanley Innovation nor the names of its contributors may be used to endorse or promote
   products derived from this software without specific prior written permission.
THIS SOFTWARE IS PROVIDED BY THE COPYRIGHT HOLDERS AND CONTRIBUTORS "AS IS" AND ANY EXPRESS OR IMPLIED WAR-
RANTIES, INCLUDING, BUT NOT LIMITED TO, THE IMPLIED WARRANTIES OF MERCHANTABILITY AND FITNESS FOR A PARTICULAR
PURPOSE ARE DISCLAIMED. IN NO EVENT SHALL THE COPYRIGHT HOLDER OR CONTRIBUTORS BE LIABLE FOR ANY DIRECT, IN-
DIRECT, INCIDENTAL, SPECIAL, EXEMPLARY, OR CONSEQUENTIAL DAMAGES (INCLUDING, BUT NOT LIMITED TO, PROCUREMENT
OF SUBSTITUTE GOODS OR SERVICES; LOSS OF USE, DATA, OR PROFITS; OR BUSINESS INTERRUPTION) HOWEVER CAUSED AND
ON ANY THEORY OF LIABILITY, WHETHER IN CONTRACT, STRICT LIABILITY, OR TORT (INCLUDING NEGLIGENCE OR OTHERWISE)
ARISING IN ANY WAY OUT OF THE USE OF THIS SOFTWARE, EVEN IF ADVISED OF THE POSSIBILITY OF SUCH DAMAGE.
-->
<robot name="pan_tilt_kinect_one" xmlns:xacro="http://ros.org/wiki/xacro">
	<xacro:include filename="$(find vector_description)/urdf/sensors/kinect_one_sensor.urdf.xacro"/>

    <property name="M_PI" value="3.14159"/>

    <xacro:macro name="pan_tilt_kinect_one" params="rgbd_prefix parent *origin">  
        
        <joint name="pan_base_joint" type="fixed">
            <xacro:insert_block name="origin" />
            <parent link="${parent}" />
            <child link="pan_base_link" />
        </joint>
        
	    <link name="pan_base_link">
			<visual>
				<geometry>
					<mesh filename="package://vector_description/meshes/sensors/visual/pan_actuator.dae" />
				</geometry>
			</visual>
			<collision>
				<geometry>
					<mesh filename="package://vector_description/meshes/sensors/collision/pan_actuator_collision.STL" />
				</geometry>
			</collision>
            <inertial>
                <mass value="0.1"/>
                <origin xyz="0 0 0" rpy="0 0 0"/>
                <inertia ixx="0.01"  ixy="0.0"  ixz="0.0"
                         iyy="0.01"  iyz="0.0"
                         izz="0.01" />
            </inertial>
		</link>
		
        <joint name="pan_joint" type="revolute">
            <origin xyz="0 0 0.0985" rpy="0 0 0" />
            <axis xyz="0 0 1"/>
            <parent link="pan_base_link" />
            <child link="pan_link" />
            <limit effort="6.0" lower="-1.570796326794897" upper="1.570796326794897" velocity="6.597"/>
        </joint>
        
        <transmission name="pan_trans" type="SimpleTransmission">
			<type>transmission_interface/SimpleTransmission</type>
			<joint name="pan_joint">
				<hardwareInterface>PositionJointInterface</hardwareInterface>
			</joint>
			<actuator name="pan_actuator">
				<mechanicalReduction>1</mechanicalReduction>
			</actuator>
		</transmission>
        
	    <link name="pan_link">
			<visual>
				<geometry>
					<mesh filename="package://vector_description/meshes/sensors/visual/tilt_actuator.dae" />
				</geometry>
			</visual>
			<collision>
			    <origin xyz="0 0 0" rpy="0 0 0" />
				<geometry>
					<mesh filename="package://vector_description/meshes/sensors/collision/tilt_actuator_collision.STL" />
				</geometry>
			</collision>
            <inertial>
                <mass value="0.1"/>
                <origin xyz="0 0 0" rpy="0 0 0"/>
                <inertia ixx="0.01"  ixy="0.0"  ixz="0.0"
                         iyy="0.01"  iyz="0.0"
                         izz="0.01" />
            </inertial>
		</link>

        <joint name="tilt_joint" type="revolute">
            <origin xyz="0 0 0" rpy="0 0 0" />
            <axis xyz="0 1 0"/>
            <parent link="pan_link" />
            <child link="tilt_link" />
            <limit effort="6.0" lower="-1.047197551196598" upper="1.570796326794897" velocity="6.597"/>
        </joint>

        <transmission name="tilt_trans" type="SimpleTransmission">
			<type>transmission_interface/SimpleTransmission</type>
			<joint name="tilt_joint">
				<hardwareInterface>PositionJointInterface</hardwareInterface>
			</joint>
			<actuator name="tilt_actuator">
				<mechanicalReduction>1</mechanicalReduction>
			</actuator>
		</transmission>
        
	    <link name="tilt_link">
			<visual>
				<geometry>
					<mesh filename="package://vector_description/meshes/sensors/visual/tilt_bracket.dae" />
				</geometry>
			</visual>
			<collision>
				<geometry>
					<mesh filename="package://vector_description/meshes/sensors/collision/tilt_bracket_collision.STL" />
				</geometry>
			</collision>
            <inertial>
                <mass value="0.1"/>
                <origin xyz="0 0 0" rpy="0 0 0"/>
                <inertia ixx="0.01"  ixy="0.0"  ixz="0.0"
                         iyy="0.01"  iyz="0.0"
                         izz="0.01" />
            </inertial>
		</link>
		
		<xacro:kinect_one_sensor prefix="${rgbd_prefix}" parent="tilt_link">
			<origin xyz="0 0 0.036" rpy="0 0 0" />
		</xacro:kinect_one_sensor>
    </xacro:macro>

</robot>
