<?xml version="1.0"?>
<!--
Software License Agreement (BSD)
\file      omni_structure.urdf.xacro
\authors   Patrick Hussey
\copyright Copyright (c) 2015, Stanley Innovation, Inc., All rights reserved.
Redistribution and use in source and binary forms, with or without modification, are permitted provided that
the following conditions are met:
 * Redistributions of source code must retain the above copyright notice, this list of conditions and the
   following disclaimer.
 * Redistributions in binary form must reproduce the above copyright notice, this list of conditions and the
   following disclaimer in the documentation and/or other materials provided with the distribution.
 * Neither the name of Stanley Innovation, Inc. nor the names of its contributors may be used to endorse or promote
   products derived from this software without specific prior written permission.
THIS SOFTWARE IS PROVIDED BY THE COPYRIGHT HOLDERS AND CONTRIBUTORS "AS IS" AND ANY EXPRESS OR IMPLIED WAR-
RANTIES, INCLUDING, BUT NOT LIMITED TO, THE IMPLIED WARRANTIES OF MERCHANTABILITY AND FITNESS FOR A PARTICULAR
PURPOSE ARE DISCLAIMED. IN NO EVENT SHALL THE COPYRIGHT HOLDER OR CONTRIBUTORS BE LIABLE FOR ANY DIRECT, IN-
DIRECT, INCIDENTAL, SPECIAL, EXEMPLARY, OR CONSEQUENTIAL DAMAGES (INCLUDING, BUT NOT LIMITED TO, PROCUREMENT
OF SUBSTITUTE GOODS OR SERVICES; LOSS OF USE, DATA, OR PROFITS; OR BUSINESS INTERRUPTION) HOWEVER CAUSED AND
ON ANY THEORY OF LIABILITY, WHETHER IN CONTRACT, STRICT LIABILITY, OR TORT (INCLUDING NEGLIGENCE OR OTHERWISE)
ARISING IN ANY WAY OUT OF THE USE OF THIS SOFTWARE, EVEN IF ADVISED OF THE POSSIBILITY OF SUCH DAMAGE.
-->
<robot xmlns:xacro="http://ros.org/wiki/xacro" name="vector_linear_actuator">

	<xacro:macro name="vector_linear_actuator" params="parent *origin">
        
        
        <joint name="linear_actuator_joint" type="fixed">
            <xacro:insert_block name="origin" />
            <parent link="${parent}" />
            <child link="linear_actuator_fixed_link" />
        </joint>
        
	    <link name="linear_actuator_fixed_link">
			<visual>
				<geometry>
					<mesh filename="package://vector_description/meshes/linear_actuator/visual/linear_actuator.dae" />
				</geometry>
			</visual>
			<collision>
				<geometry>
					<mesh filename="package://vector_description/meshes/linear_actuator/collision/linear_actuator_collision.STL" />
				</geometry>
			</collision>
		    <inertial>
                <!--mass value="2e-06"/>
                <inertia ixx="1.1e-09" ixy="0" ixz="0" iyy="1.1e-09" iyz="0" izz="1.1e-09"/-->
                <mass value="5.098044" />
                <origin xyz="0.0 0.0 0.5" rpy="0 0 0"/>
                <inertia ixx="0.02"  ixy="0.0"  ixz="1.0" iyy="-0.03"  iyz="-0.02" izz="0.0" />
		    </inertial>			    
		</link>
		
        <joint name="linear_joint" type="prismatic">
            <parent link="linear_actuator_fixed_link" />
            <child link = "linear_actuator_link" />
            <origin xyz="0 0 0" rpy="0 0 0" />
            <axis xyz="0 0 1" />
            <limit lower="0.0" upper="0.855" effort="1000" velocity="0.20"/>
            <dynamics damping="0.0" friction="0.0"/>
        </joint>
        
        <xacro:unless value="$(optenv VECTOR_HAS_TWO_KINOVA_ARMS false)">
            <link name="linear_actuator_link">
			    <visual>
				    <geometry>
					    <mesh filename="package://vector_description/meshes/linear_actuator/visual/linear_carraige.dae" />
				    </geometry>
			    </visual>
			    <collision>
				    <geometry>
					    <mesh filename="package://vector_description/meshes/linear_actuator/collision/linear_carraige_collision.STL" />
				    </geometry>
			    </collision>
		        <inertial>
                    <!--mass value="2e-06"/>
                    <inertia ixx="1.1e-09" ixy="0" ixz="0" iyy="1.1e-09" iyz="0" izz="1.1e-09"/-->
                    <mass value="0.217" />
                    <origin xyz="0 -0.001 0" rpy="0 0 0"/>
                    <inertia ixx="0.0" ixy="0.0"  ixz="1.0"
                             iyy="0.0" iyz="0.0"
                             izz="0.0" />
		        </inertial>
		    </link>
		</xacro:unless>

        <xacro:if value="$(optenv VECTOR_HAS_TWO_KINOVA_ARMS false)">
            <link name="linear_actuator_link">
			    <visual>
				    <geometry>
					    <mesh filename="package://vector_description/meshes/linear_actuator/visual/linear_carraige_dual_front.dae" />
				    </geometry>
			    </visual>
			    <collision>
				    <geometry>
					    <mesh filename="package://vector_description/meshes/linear_actuator/collision/linear_carraige_dual_front.STL" />
				    </geometry>
			    </collision>
		        <inertial>
			        <mass value="2e-06"/>
			        <inertia ixx="1.1e-09" ixy="0" ixz="0" iyy="1.1e-09" iyz="0" izz="1.1e-09"/>
		        </inertial>
		    </link>
		</xacro:if>

        <transmission name="linear_trans">
            <type>transmission_interface/SimpleTransmission</type>
            <joint name="linear_joint">
                <hardwareInterface>PositionJointInterface</hardwareInterface>
            </joint>
            <actuator name="linear_motor">
                <mechanicalReduction>1</mechanicalReduction>
            </actuator>
        </transmission>             
   
    </xacro:macro>

</robot>
